[2021-02-23 23:15:26,266] {scheduler_job.py:182} INFO - Started process (PID=30) to work on /opt/airflow/dags/dag_trigger_airbyte_connection.py
[2021-02-23 23:15:26,266] {scheduler_job.py:629} INFO - Processing file /opt/airflow/dags/dag_trigger_airbyte_connection.py for tasks to queue
[2021-02-23 23:15:26,267] {logging_mixin.py:104} INFO - [2021-02-23 23:15:26,267] {dagbag.py:448} INFO - Filling up the DagBag from /opt/airflow/dags/dag_trigger_airbyte_connection.py
[2021-02-23 23:15:26,270] {logging_mixin.py:104} INFO - [2021-02-23 23:15:26,270] {dagbag.py:305} ERROR - Failed to import: /opt/airflow/dags/dag_trigger_airbyte_connection.py
Traceback (most recent call last):
  File "/home/airflow/.local/lib/python3.6/site-packages/airflow/models/dagbag.py", line 302, in _load_modules_from_file
    loader.exec_module(new_module)
  File "<frozen importlib._bootstrap_external>", line 678, in exec_module
  File "<frozen importlib._bootstrap>", line 219, in _call_with_frames_removed
  File "/opt/airflow/dags/dag_trigger_airbyte_connection.py", line 4, in <module>
    from plugin.operator import AirbyteTriggerSyncOperator
ModuleNotFoundError: No module named 'plugin'
[2021-02-23 23:15:26,271] {scheduler_job.py:641} WARNING - No viable dags retrieved from /opt/airflow/dags/dag_trigger_airbyte_connection.py
[2021-02-23 23:15:26,309] {scheduler_job.py:190} INFO - Processing /opt/airflow/dags/dag_trigger_airbyte_connection.py took 0.046 seconds
[2021-02-23 23:15:56,864] {scheduler_job.py:182} INFO - Started process (PID=57) to work on /opt/airflow/dags/dag_trigger_airbyte_connection.py
[2021-02-23 23:15:56,865] {scheduler_job.py:629} INFO - Processing file /opt/airflow/dags/dag_trigger_airbyte_connection.py for tasks to queue
[2021-02-23 23:15:56,867] {logging_mixin.py:104} INFO - [2021-02-23 23:15:56,867] {dagbag.py:448} INFO - Filling up the DagBag from /opt/airflow/dags/dag_trigger_airbyte_connection.py
[2021-02-23 23:15:56,871] {logging_mixin.py:104} INFO - [2021-02-23 23:15:56,870] {dagbag.py:305} ERROR - Failed to import: /opt/airflow/dags/dag_trigger_airbyte_connection.py
Traceback (most recent call last):
  File "/home/airflow/.local/lib/python3.6/site-packages/airflow/models/dagbag.py", line 302, in _load_modules_from_file
    loader.exec_module(new_module)
  File "<frozen importlib._bootstrap_external>", line 678, in exec_module
  File "<frozen importlib._bootstrap>", line 219, in _call_with_frames_removed
  File "/opt/airflow/dags/dag_trigger_airbyte_connection.py", line 4, in <module>
    from plugin.operator import AirbyteTriggerSyncOperator
ModuleNotFoundError: No module named 'plugin'
[2021-02-23 23:15:56,872] {scheduler_job.py:641} WARNING - No viable dags retrieved from /opt/airflow/dags/dag_trigger_airbyte_connection.py
[2021-02-23 23:15:57,007] {scheduler_job.py:190} INFO - Processing /opt/airflow/dags/dag_trigger_airbyte_connection.py took 0.148 seconds
[2021-02-23 23:16:27,178] {scheduler_job.py:182} INFO - Started process (PID=84) to work on /opt/airflow/dags/dag_trigger_airbyte_connection.py
[2021-02-23 23:16:27,179] {scheduler_job.py:629} INFO - Processing file /opt/airflow/dags/dag_trigger_airbyte_connection.py for tasks to queue
[2021-02-23 23:16:27,180] {logging_mixin.py:104} INFO - [2021-02-23 23:16:27,180] {dagbag.py:448} INFO - Filling up the DagBag from /opt/airflow/dags/dag_trigger_airbyte_connection.py
[2021-02-23 23:16:27,182] {logging_mixin.py:104} INFO - [2021-02-23 23:16:27,182] {dagbag.py:305} ERROR - Failed to import: /opt/airflow/dags/dag_trigger_airbyte_connection.py
Traceback (most recent call last):
  File "/home/airflow/.local/lib/python3.6/site-packages/airflow/models/dagbag.py", line 302, in _load_modules_from_file
    loader.exec_module(new_module)
  File "<frozen importlib._bootstrap_external>", line 678, in exec_module
  File "<frozen importlib._bootstrap>", line 219, in _call_with_frames_removed
  File "/opt/airflow/dags/dag_trigger_airbyte_connection.py", line 4, in <module>
    from plugin.operator import AirbyteTriggerSyncOperator
ModuleNotFoundError: No module named 'plugin'
[2021-02-23 23:16:27,183] {scheduler_job.py:641} WARNING - No viable dags retrieved from /opt/airflow/dags/dag_trigger_airbyte_connection.py
[2021-02-23 23:16:27,660] {scheduler_job.py:190} INFO - Processing /opt/airflow/dags/dag_trigger_airbyte_connection.py took 0.485 seconds
[2021-02-23 23:16:57,886] {scheduler_job.py:182} INFO - Started process (PID=111) to work on /opt/airflow/dags/dag_trigger_airbyte_connection.py
[2021-02-23 23:16:57,887] {scheduler_job.py:629} INFO - Processing file /opt/airflow/dags/dag_trigger_airbyte_connection.py for tasks to queue
[2021-02-23 23:16:57,887] {logging_mixin.py:104} INFO - [2021-02-23 23:16:57,887] {dagbag.py:448} INFO - Filling up the DagBag from /opt/airflow/dags/dag_trigger_airbyte_connection.py
[2021-02-23 23:16:57,889] {logging_mixin.py:104} INFO - [2021-02-23 23:16:57,888] {dagbag.py:305} ERROR - Failed to import: /opt/airflow/dags/dag_trigger_airbyte_connection.py
Traceback (most recent call last):
  File "/home/airflow/.local/lib/python3.6/site-packages/airflow/models/dagbag.py", line 302, in _load_modules_from_file
    loader.exec_module(new_module)
  File "<frozen importlib._bootstrap_external>", line 678, in exec_module
  File "<frozen importlib._bootstrap>", line 219, in _call_with_frames_removed
  File "/opt/airflow/dags/dag_trigger_airbyte_connection.py", line 4, in <module>
    from plugin.operator import AirbyteTriggerSyncOperator
ModuleNotFoundError: No module named 'plugin'
[2021-02-23 23:16:57,889] {scheduler_job.py:641} WARNING - No viable dags retrieved from /opt/airflow/dags/dag_trigger_airbyte_connection.py
[2021-02-23 23:16:58,019] {scheduler_job.py:190} INFO - Processing /opt/airflow/dags/dag_trigger_airbyte_connection.py took 0.135 seconds
[2021-02-23 23:26:15,072] {scheduler_job.py:182} INFO - Started process (PID=43) to work on /opt/airflow/dags/dag_trigger_airbyte_connection.py
[2021-02-23 23:26:15,073] {scheduler_job.py:629} INFO - Processing file /opt/airflow/dags/dag_trigger_airbyte_connection.py for tasks to queue
[2021-02-23 23:26:15,074] {logging_mixin.py:104} INFO - [2021-02-23 23:26:15,073] {dagbag.py:448} INFO - Filling up the DagBag from /opt/airflow/dags/dag_trigger_airbyte_connection.py
[2021-02-23 23:26:15,077] {logging_mixin.py:104} INFO - [2021-02-23 23:26:15,076] {dagbag.py:305} ERROR - Failed to import: /opt/airflow/dags/dag_trigger_airbyte_connection.py
Traceback (most recent call last):
  File "/home/airflow/.local/lib/python3.6/site-packages/airflow/models/dagbag.py", line 302, in _load_modules_from_file
    loader.exec_module(new_module)
  File "<frozen importlib._bootstrap_external>", line 678, in exec_module
  File "<frozen importlib._bootstrap>", line 219, in _call_with_frames_removed
  File "/opt/airflow/dags/dag_trigger_airbyte_connection.py", line 4, in <module>
    from plugin.operator import AirbyteTriggerSyncOperator
ModuleNotFoundError: No module named 'plugin'
[2021-02-23 23:26:15,078] {scheduler_job.py:641} WARNING - No viable dags retrieved from /opt/airflow/dags/dag_trigger_airbyte_connection.py
[2021-02-23 23:26:15,132] {scheduler_job.py:190} INFO - Processing /opt/airflow/dags/dag_trigger_airbyte_connection.py took 0.063 seconds
[2021-02-23 23:26:46,916] {scheduler_job.py:182} INFO - Started process (PID=70) to work on /opt/airflow/dags/dag_trigger_airbyte_connection.py
[2021-02-23 23:26:46,918] {scheduler_job.py:629} INFO - Processing file /opt/airflow/dags/dag_trigger_airbyte_connection.py for tasks to queue
[2021-02-23 23:26:46,919] {logging_mixin.py:104} INFO - [2021-02-23 23:26:46,919] {dagbag.py:448} INFO - Filling up the DagBag from /opt/airflow/dags/dag_trigger_airbyte_connection.py
[2021-02-23 23:26:46,923] {logging_mixin.py:104} INFO - [2021-02-23 23:26:46,922] {dagbag.py:305} ERROR - Failed to import: /opt/airflow/dags/dag_trigger_airbyte_connection.py
Traceback (most recent call last):
  File "/home/airflow/.local/lib/python3.6/site-packages/airflow/models/dagbag.py", line 302, in _load_modules_from_file
    loader.exec_module(new_module)
  File "<frozen importlib._bootstrap_external>", line 678, in exec_module
  File "<frozen importlib._bootstrap>", line 219, in _call_with_frames_removed
  File "/opt/airflow/dags/dag_trigger_airbyte_connection.py", line 4, in <module>
    from plugin.operator import AirbyteTriggerSyncOperator
ModuleNotFoundError: No module named 'plugin'
[2021-02-23 23:26:46,924] {scheduler_job.py:641} WARNING - No viable dags retrieved from /opt/airflow/dags/dag_trigger_airbyte_connection.py
[2021-02-23 23:26:47,102] {scheduler_job.py:190} INFO - Processing /opt/airflow/dags/dag_trigger_airbyte_connection.py took 0.192 seconds
[2021-02-23 23:27:17,293] {scheduler_job.py:182} INFO - Started process (PID=95) to work on /opt/airflow/dags/dag_trigger_airbyte_connection.py
[2021-02-23 23:27:17,294] {scheduler_job.py:629} INFO - Processing file /opt/airflow/dags/dag_trigger_airbyte_connection.py for tasks to queue
[2021-02-23 23:27:17,295] {logging_mixin.py:104} INFO - [2021-02-23 23:27:17,294] {dagbag.py:448} INFO - Filling up the DagBag from /opt/airflow/dags/dag_trigger_airbyte_connection.py
[2021-02-23 23:27:17,297] {logging_mixin.py:104} INFO - [2021-02-23 23:27:17,297] {dagbag.py:305} ERROR - Failed to import: /opt/airflow/dags/dag_trigger_airbyte_connection.py
Traceback (most recent call last):
  File "/home/airflow/.local/lib/python3.6/site-packages/airflow/models/dagbag.py", line 302, in _load_modules_from_file
    loader.exec_module(new_module)
  File "<frozen importlib._bootstrap_external>", line 678, in exec_module
  File "<frozen importlib._bootstrap>", line 219, in _call_with_frames_removed
  File "/opt/airflow/dags/dag_trigger_airbyte_connection.py", line 4, in <module>
    from plugin.operator import AirbyteTriggerSyncOperator
ModuleNotFoundError: No module named 'plugin'
[2021-02-23 23:27:17,298] {scheduler_job.py:641} WARNING - No viable dags retrieved from /opt/airflow/dags/dag_trigger_airbyte_connection.py
[2021-02-23 23:27:17,339] {scheduler_job.py:190} INFO - Processing /opt/airflow/dags/dag_trigger_airbyte_connection.py took 0.051 seconds
[2021-02-23 23:27:47,429] {scheduler_job.py:182} INFO - Started process (PID=121) to work on /opt/airflow/dags/dag_trigger_airbyte_connection.py
[2021-02-23 23:27:47,430] {scheduler_job.py:629} INFO - Processing file /opt/airflow/dags/dag_trigger_airbyte_connection.py for tasks to queue
[2021-02-23 23:27:47,430] {logging_mixin.py:104} INFO - [2021-02-23 23:27:47,430] {dagbag.py:448} INFO - Filling up the DagBag from /opt/airflow/dags/dag_trigger_airbyte_connection.py
[2021-02-23 23:27:47,432] {logging_mixin.py:104} INFO - [2021-02-23 23:27:47,432] {dagbag.py:305} ERROR - Failed to import: /opt/airflow/dags/dag_trigger_airbyte_connection.py
Traceback (most recent call last):
  File "/home/airflow/.local/lib/python3.6/site-packages/airflow/models/dagbag.py", line 302, in _load_modules_from_file
    loader.exec_module(new_module)
  File "<frozen importlib._bootstrap_external>", line 678, in exec_module
  File "<frozen importlib._bootstrap>", line 219, in _call_with_frames_removed
  File "/opt/airflow/dags/dag_trigger_airbyte_connection.py", line 4, in <module>
    from plugin.operator import AirbyteTriggerSyncOperator
ModuleNotFoundError: No module named 'plugin'
[2021-02-23 23:27:47,433] {scheduler_job.py:641} WARNING - No viable dags retrieved from /opt/airflow/dags/dag_trigger_airbyte_connection.py
[2021-02-23 23:27:47,593] {scheduler_job.py:190} INFO - Processing /opt/airflow/dags/dag_trigger_airbyte_connection.py took 0.168 seconds
[2021-02-23 23:28:17,832] {scheduler_job.py:182} INFO - Started process (PID=147) to work on /opt/airflow/dags/dag_trigger_airbyte_connection.py
[2021-02-23 23:28:17,833] {scheduler_job.py:629} INFO - Processing file /opt/airflow/dags/dag_trigger_airbyte_connection.py for tasks to queue
[2021-02-23 23:28:17,833] {logging_mixin.py:104} INFO - [2021-02-23 23:28:17,833] {dagbag.py:448} INFO - Filling up the DagBag from /opt/airflow/dags/dag_trigger_airbyte_connection.py
[2021-02-23 23:28:17,835] {logging_mixin.py:104} INFO - [2021-02-23 23:28:17,835] {dagbag.py:305} ERROR - Failed to import: /opt/airflow/dags/dag_trigger_airbyte_connection.py
Traceback (most recent call last):
  File "/home/airflow/.local/lib/python3.6/site-packages/airflow/models/dagbag.py", line 302, in _load_modules_from_file
    loader.exec_module(new_module)
  File "<frozen importlib._bootstrap_external>", line 678, in exec_module
  File "<frozen importlib._bootstrap>", line 219, in _call_with_frames_removed
  File "/opt/airflow/dags/dag_trigger_airbyte_connection.py", line 4, in <module>
    from plugin.operator import AirbyteTriggerSyncOperator
ModuleNotFoundError: No module named 'plugin'
[2021-02-23 23:28:17,836] {scheduler_job.py:641} WARNING - No viable dags retrieved from /opt/airflow/dags/dag_trigger_airbyte_connection.py
[2021-02-23 23:28:17,876] {scheduler_job.py:190} INFO - Processing /opt/airflow/dags/dag_trigger_airbyte_connection.py took 0.047 seconds
[2021-02-23 23:28:48,705] {scheduler_job.py:182} INFO - Started process (PID=172) to work on /opt/airflow/dags/dag_trigger_airbyte_connection.py
[2021-02-23 23:28:48,708] {scheduler_job.py:629} INFO - Processing file /opt/airflow/dags/dag_trigger_airbyte_connection.py for tasks to queue
[2021-02-23 23:28:48,710] {logging_mixin.py:104} INFO - [2021-02-23 23:28:48,709] {dagbag.py:448} INFO - Filling up the DagBag from /opt/airflow/dags/dag_trigger_airbyte_connection.py
[2021-02-23 23:28:48,714] {logging_mixin.py:104} INFO - [2021-02-23 23:28:48,713] {dagbag.py:305} ERROR - Failed to import: /opt/airflow/dags/dag_trigger_airbyte_connection.py
Traceback (most recent call last):
  File "/home/airflow/.local/lib/python3.6/site-packages/airflow/models/dagbag.py", line 302, in _load_modules_from_file
    loader.exec_module(new_module)
  File "<frozen importlib._bootstrap_external>", line 678, in exec_module
  File "<frozen importlib._bootstrap>", line 219, in _call_with_frames_removed
  File "/opt/airflow/dags/dag_trigger_airbyte_connection.py", line 4, in <module>
    from plugin.operator import AirbyteTriggerSyncOperator
ModuleNotFoundError: No module named 'plugin'
[2021-02-23 23:28:48,715] {scheduler_job.py:641} WARNING - No viable dags retrieved from /opt/airflow/dags/dag_trigger_airbyte_connection.py
[2021-02-23 23:28:48,774] {scheduler_job.py:190} INFO - Processing /opt/airflow/dags/dag_trigger_airbyte_connection.py took 0.076 seconds
[2021-02-23 23:29:19,398] {scheduler_job.py:182} INFO - Started process (PID=199) to work on /opt/airflow/dags/dag_trigger_airbyte_connection.py
[2021-02-23 23:29:19,400] {scheduler_job.py:629} INFO - Processing file /opt/airflow/dags/dag_trigger_airbyte_connection.py for tasks to queue
[2021-02-23 23:29:19,401] {logging_mixin.py:104} INFO - [2021-02-23 23:29:19,401] {dagbag.py:448} INFO - Filling up the DagBag from /opt/airflow/dags/dag_trigger_airbyte_connection.py
[2021-02-23 23:29:19,406] {logging_mixin.py:104} INFO - [2021-02-23 23:29:19,404] {dagbag.py:305} ERROR - Failed to import: /opt/airflow/dags/dag_trigger_airbyte_connection.py
Traceback (most recent call last):
  File "/home/airflow/.local/lib/python3.6/site-packages/airflow/models/dagbag.py", line 302, in _load_modules_from_file
    loader.exec_module(new_module)
  File "<frozen importlib._bootstrap_external>", line 678, in exec_module
  File "<frozen importlib._bootstrap>", line 219, in _call_with_frames_removed
  File "/opt/airflow/dags/dag_trigger_airbyte_connection.py", line 4, in <module>
    from plugin.operator import AirbyteTriggerSyncOperator
ModuleNotFoundError: No module named 'plugin'
[2021-02-23 23:29:19,406] {scheduler_job.py:641} WARNING - No viable dags retrieved from /opt/airflow/dags/dag_trigger_airbyte_connection.py
[2021-02-23 23:29:19,599] {scheduler_job.py:190} INFO - Processing /opt/airflow/dags/dag_trigger_airbyte_connection.py took 0.207 seconds
[2021-02-23 23:29:50,173] {scheduler_job.py:182} INFO - Started process (PID=229) to work on /opt/airflow/dags/dag_trigger_airbyte_connection.py
[2021-02-23 23:29:50,174] {scheduler_job.py:629} INFO - Processing file /opt/airflow/dags/dag_trigger_airbyte_connection.py for tasks to queue
[2021-02-23 23:29:50,175] {logging_mixin.py:104} INFO - [2021-02-23 23:29:50,175] {dagbag.py:448} INFO - Filling up the DagBag from /opt/airflow/dags/dag_trigger_airbyte_connection.py
[2021-02-23 23:29:50,178] {logging_mixin.py:104} INFO - [2021-02-23 23:29:50,177] {dagbag.py:305} ERROR - Failed to import: /opt/airflow/dags/dag_trigger_airbyte_connection.py
Traceback (most recent call last):
  File "/home/airflow/.local/lib/python3.6/site-packages/airflow/models/dagbag.py", line 302, in _load_modules_from_file
    loader.exec_module(new_module)
  File "<frozen importlib._bootstrap_external>", line 678, in exec_module
  File "<frozen importlib._bootstrap>", line 219, in _call_with_frames_removed
  File "/opt/airflow/dags/dag_trigger_airbyte_connection.py", line 4, in <module>
    from plugin.operator import AirbyteTriggerSyncOperator
ModuleNotFoundError: No module named 'plugin'
[2021-02-23 23:29:50,178] {scheduler_job.py:641} WARNING - No viable dags retrieved from /opt/airflow/dags/dag_trigger_airbyte_connection.py
[2021-02-23 23:29:50,213] {scheduler_job.py:190} INFO - Processing /opt/airflow/dags/dag_trigger_airbyte_connection.py took 0.043 seconds
[2021-02-23 23:30:20,909] {scheduler_job.py:182} INFO - Started process (PID=256) to work on /opt/airflow/dags/dag_trigger_airbyte_connection.py
[2021-02-23 23:30:20,910] {scheduler_job.py:629} INFO - Processing file /opt/airflow/dags/dag_trigger_airbyte_connection.py for tasks to queue
[2021-02-23 23:30:20,910] {logging_mixin.py:104} INFO - [2021-02-23 23:30:20,910] {dagbag.py:448} INFO - Filling up the DagBag from /opt/airflow/dags/dag_trigger_airbyte_connection.py
[2021-02-23 23:30:20,912] {logging_mixin.py:104} INFO - [2021-02-23 23:30:20,911] {dagbag.py:305} ERROR - Failed to import: /opt/airflow/dags/dag_trigger_airbyte_connection.py
Traceback (most recent call last):
  File "/home/airflow/.local/lib/python3.6/site-packages/airflow/models/dagbag.py", line 302, in _load_modules_from_file
    loader.exec_module(new_module)
  File "<frozen importlib._bootstrap_external>", line 678, in exec_module
  File "<frozen importlib._bootstrap>", line 219, in _call_with_frames_removed
  File "/opt/airflow/dags/dag_trigger_airbyte_connection.py", line 4, in <module>
    from plugin.operator import AirbyteTriggerSyncOperator
ModuleNotFoundError: No module named 'plugin'
[2021-02-23 23:30:20,912] {scheduler_job.py:641} WARNING - No viable dags retrieved from /opt/airflow/dags/dag_trigger_airbyte_connection.py
[2021-02-23 23:30:20,945] {scheduler_job.py:190} INFO - Processing /opt/airflow/dags/dag_trigger_airbyte_connection.py took 0.038 seconds
[2021-02-23 23:30:51,317] {scheduler_job.py:182} INFO - Started process (PID=280) to work on /opt/airflow/dags/dag_trigger_airbyte_connection.py
[2021-02-23 23:30:51,319] {scheduler_job.py:629} INFO - Processing file /opt/airflow/dags/dag_trigger_airbyte_connection.py for tasks to queue
[2021-02-23 23:30:51,321] {logging_mixin.py:104} INFO - [2021-02-23 23:30:51,321] {dagbag.py:448} INFO - Filling up the DagBag from /opt/airflow/dags/dag_trigger_airbyte_connection.py
[2021-02-23 23:30:51,328] {logging_mixin.py:104} INFO - [2021-02-23 23:30:51,326] {dagbag.py:305} ERROR - Failed to import: /opt/airflow/dags/dag_trigger_airbyte_connection.py
Traceback (most recent call last):
  File "/home/airflow/.local/lib/python3.6/site-packages/airflow/models/dagbag.py", line 302, in _load_modules_from_file
    loader.exec_module(new_module)
  File "<frozen importlib._bootstrap_external>", line 678, in exec_module
  File "<frozen importlib._bootstrap>", line 219, in _call_with_frames_removed
  File "/opt/airflow/dags/dag_trigger_airbyte_connection.py", line 4, in <module>
    from plugin.operator import AirbyteTriggerSyncOperator
ModuleNotFoundError: No module named 'plugin'
[2021-02-23 23:30:51,329] {scheduler_job.py:641} WARNING - No viable dags retrieved from /opt/airflow/dags/dag_trigger_airbyte_connection.py
[2021-02-23 23:30:51,411] {scheduler_job.py:190} INFO - Processing /opt/airflow/dags/dag_trigger_airbyte_connection.py took 0.101 seconds
[2021-02-23 23:31:21,490] {scheduler_job.py:182} INFO - Started process (PID=307) to work on /opt/airflow/dags/dag_trigger_airbyte_connection.py
[2021-02-23 23:31:21,491] {scheduler_job.py:629} INFO - Processing file /opt/airflow/dags/dag_trigger_airbyte_connection.py for tasks to queue
[2021-02-23 23:31:21,491] {logging_mixin.py:104} INFO - [2021-02-23 23:31:21,491] {dagbag.py:448} INFO - Filling up the DagBag from /opt/airflow/dags/dag_trigger_airbyte_connection.py
[2021-02-23 23:31:21,493] {logging_mixin.py:104} INFO - [2021-02-23 23:31:21,493] {dagbag.py:305} ERROR - Failed to import: /opt/airflow/dags/dag_trigger_airbyte_connection.py
Traceback (most recent call last):
  File "/home/airflow/.local/lib/python3.6/site-packages/airflow/models/dagbag.py", line 302, in _load_modules_from_file
    loader.exec_module(new_module)
  File "<frozen importlib._bootstrap_external>", line 678, in exec_module
  File "<frozen importlib._bootstrap>", line 219, in _call_with_frames_removed
  File "/opt/airflow/dags/dag_trigger_airbyte_connection.py", line 4, in <module>
    from plugin.operator import AirbyteTriggerSyncOperator
ModuleNotFoundError: No module named 'plugin'
[2021-02-23 23:31:21,494] {scheduler_job.py:641} WARNING - No viable dags retrieved from /opt/airflow/dags/dag_trigger_airbyte_connection.py
[2021-02-23 23:31:21,533] {scheduler_job.py:190} INFO - Processing /opt/airflow/dags/dag_trigger_airbyte_connection.py took 0.046 seconds
[2021-02-23 23:31:51,836] {scheduler_job.py:182} INFO - Started process (PID=329) to work on /opt/airflow/dags/dag_trigger_airbyte_connection.py
[2021-02-23 23:31:51,839] {scheduler_job.py:629} INFO - Processing file /opt/airflow/dags/dag_trigger_airbyte_connection.py for tasks to queue
[2021-02-23 23:31:51,840] {logging_mixin.py:104} INFO - [2021-02-23 23:31:51,840] {dagbag.py:448} INFO - Filling up the DagBag from /opt/airflow/dags/dag_trigger_airbyte_connection.py
[2021-02-23 23:31:51,845] {logging_mixin.py:104} INFO - [2021-02-23 23:31:51,844] {dagbag.py:305} ERROR - Failed to import: /opt/airflow/dags/dag_trigger_airbyte_connection.py
Traceback (most recent call last):
  File "/home/airflow/.local/lib/python3.6/site-packages/airflow/models/dagbag.py", line 302, in _load_modules_from_file
    loader.exec_module(new_module)
  File "<frozen importlib._bootstrap_external>", line 678, in exec_module
  File "<frozen importlib._bootstrap>", line 219, in _call_with_frames_removed
  File "/opt/airflow/dags/dag_trigger_airbyte_connection.py", line 4, in <module>
    from plugin.operator import AirbyteTriggerSyncOperator
ModuleNotFoundError: No module named 'plugin'
[2021-02-23 23:31:51,846] {scheduler_job.py:641} WARNING - No viable dags retrieved from /opt/airflow/dags/dag_trigger_airbyte_connection.py
[2021-02-23 23:31:51,999] {scheduler_job.py:190} INFO - Processing /opt/airflow/dags/dag_trigger_airbyte_connection.py took 0.171 seconds
[2021-02-23 23:32:22,802] {scheduler_job.py:182} INFO - Started process (PID=356) to work on /opt/airflow/dags/dag_trigger_airbyte_connection.py
[2021-02-23 23:32:22,804] {scheduler_job.py:629} INFO - Processing file /opt/airflow/dags/dag_trigger_airbyte_connection.py for tasks to queue
[2021-02-23 23:32:22,806] {logging_mixin.py:104} INFO - [2021-02-23 23:32:22,805] {dagbag.py:448} INFO - Filling up the DagBag from /opt/airflow/dags/dag_trigger_airbyte_connection.py
[2021-02-23 23:32:22,811] {logging_mixin.py:104} INFO - [2021-02-23 23:32:22,810] {dagbag.py:305} ERROR - Failed to import: /opt/airflow/dags/dag_trigger_airbyte_connection.py
Traceback (most recent call last):
  File "/home/airflow/.local/lib/python3.6/site-packages/airflow/models/dagbag.py", line 302, in _load_modules_from_file
    loader.exec_module(new_module)
  File "<frozen importlib._bootstrap_external>", line 678, in exec_module
  File "<frozen importlib._bootstrap>", line 219, in _call_with_frames_removed
  File "/opt/airflow/dags/dag_trigger_airbyte_connection.py", line 4, in <module>
    from plugin.operator import AirbyteTriggerSyncOperator
ModuleNotFoundError: No module named 'plugin'
[2021-02-23 23:32:22,811] {scheduler_job.py:641} WARNING - No viable dags retrieved from /opt/airflow/dags/dag_trigger_airbyte_connection.py
[2021-02-23 23:32:22,908] {scheduler_job.py:190} INFO - Processing /opt/airflow/dags/dag_trigger_airbyte_connection.py took 0.114 seconds
[2021-02-23 23:32:53,387] {scheduler_job.py:182} INFO - Started process (PID=383) to work on /opt/airflow/dags/dag_trigger_airbyte_connection.py
[2021-02-23 23:32:53,388] {scheduler_job.py:629} INFO - Processing file /opt/airflow/dags/dag_trigger_airbyte_connection.py for tasks to queue
[2021-02-23 23:32:53,389] {logging_mixin.py:104} INFO - [2021-02-23 23:32:53,389] {dagbag.py:448} INFO - Filling up the DagBag from /opt/airflow/dags/dag_trigger_airbyte_connection.py
[2021-02-23 23:32:53,391] {logging_mixin.py:104} INFO - [2021-02-23 23:32:53,390] {dagbag.py:305} ERROR - Failed to import: /opt/airflow/dags/dag_trigger_airbyte_connection.py
Traceback (most recent call last):
  File "/home/airflow/.local/lib/python3.6/site-packages/airflow/models/dagbag.py", line 302, in _load_modules_from_file
    loader.exec_module(new_module)
  File "<frozen importlib._bootstrap_external>", line 678, in exec_module
  File "<frozen importlib._bootstrap>", line 219, in _call_with_frames_removed
  File "/opt/airflow/dags/dag_trigger_airbyte_connection.py", line 4, in <module>
    from plugin.operator import AirbyteTriggerSyncOperator
ModuleNotFoundError: No module named 'plugin'
[2021-02-23 23:32:53,391] {scheduler_job.py:641} WARNING - No viable dags retrieved from /opt/airflow/dags/dag_trigger_airbyte_connection.py
[2021-02-23 23:32:53,461] {scheduler_job.py:190} INFO - Processing /opt/airflow/dags/dag_trigger_airbyte_connection.py took 0.075 seconds
[2021-02-23 23:33:23,585] {scheduler_job.py:182} INFO - Started process (PID=410) to work on /opt/airflow/dags/dag_trigger_airbyte_connection.py
[2021-02-23 23:33:23,590] {scheduler_job.py:629} INFO - Processing file /opt/airflow/dags/dag_trigger_airbyte_connection.py for tasks to queue
[2021-02-23 23:33:23,592] {logging_mixin.py:104} INFO - [2021-02-23 23:33:23,592] {dagbag.py:448} INFO - Filling up the DagBag from /opt/airflow/dags/dag_trigger_airbyte_connection.py
[2021-02-23 23:33:23,598] {logging_mixin.py:104} INFO - [2021-02-23 23:33:23,596] {dagbag.py:305} ERROR - Failed to import: /opt/airflow/dags/dag_trigger_airbyte_connection.py
Traceback (most recent call last):
  File "/home/airflow/.local/lib/python3.6/site-packages/airflow/models/dagbag.py", line 302, in _load_modules_from_file
    loader.exec_module(new_module)
  File "<frozen importlib._bootstrap_external>", line 678, in exec_module
  File "<frozen importlib._bootstrap>", line 219, in _call_with_frames_removed
  File "/opt/airflow/dags/dag_trigger_airbyte_connection.py", line 4, in <module>
    from plugin.operator import AirbyteTriggerSyncOperator
ModuleNotFoundError: No module named 'plugin'
[2021-02-23 23:33:23,599] {scheduler_job.py:641} WARNING - No viable dags retrieved from /opt/airflow/dags/dag_trigger_airbyte_connection.py
[2021-02-23 23:33:23,692] {scheduler_job.py:190} INFO - Processing /opt/airflow/dags/dag_trigger_airbyte_connection.py took 0.117 seconds
[2021-02-23 23:33:54,369] {scheduler_job.py:182} INFO - Started process (PID=437) to work on /opt/airflow/dags/dag_trigger_airbyte_connection.py
[2021-02-23 23:33:54,372] {scheduler_job.py:629} INFO - Processing file /opt/airflow/dags/dag_trigger_airbyte_connection.py for tasks to queue
[2021-02-23 23:33:54,374] {logging_mixin.py:104} INFO - [2021-02-23 23:33:54,374] {dagbag.py:448} INFO - Filling up the DagBag from /opt/airflow/dags/dag_trigger_airbyte_connection.py
[2021-02-23 23:33:54,382] {logging_mixin.py:104} INFO - [2021-02-23 23:33:54,379] {dagbag.py:305} ERROR - Failed to import: /opt/airflow/dags/dag_trigger_airbyte_connection.py
Traceback (most recent call last):
  File "/home/airflow/.local/lib/python3.6/site-packages/airflow/models/dagbag.py", line 302, in _load_modules_from_file
    loader.exec_module(new_module)
  File "<frozen importlib._bootstrap_external>", line 678, in exec_module
  File "<frozen importlib._bootstrap>", line 219, in _call_with_frames_removed
  File "/opt/airflow/dags/dag_trigger_airbyte_connection.py", line 4, in <module>
    from plugin.operator import AirbyteTriggerSyncOperator
ModuleNotFoundError: No module named 'plugin'
[2021-02-23 23:33:54,382] {scheduler_job.py:641} WARNING - No viable dags retrieved from /opt/airflow/dags/dag_trigger_airbyte_connection.py
[2021-02-23 23:33:54,525] {scheduler_job.py:190} INFO - Processing /opt/airflow/dags/dag_trigger_airbyte_connection.py took 0.165 seconds
[2021-02-23 23:34:24,780] {scheduler_job.py:182} INFO - Started process (PID=464) to work on /opt/airflow/dags/dag_trigger_airbyte_connection.py
[2021-02-23 23:34:24,781] {scheduler_job.py:629} INFO - Processing file /opt/airflow/dags/dag_trigger_airbyte_connection.py for tasks to queue
[2021-02-23 23:34:24,782] {logging_mixin.py:104} INFO - [2021-02-23 23:34:24,782] {dagbag.py:448} INFO - Filling up the DagBag from /opt/airflow/dags/dag_trigger_airbyte_connection.py
[2021-02-23 23:34:24,785] {logging_mixin.py:104} INFO - [2021-02-23 23:34:24,784] {dagbag.py:305} ERROR - Failed to import: /opt/airflow/dags/dag_trigger_airbyte_connection.py
Traceback (most recent call last):
  File "/home/airflow/.local/lib/python3.6/site-packages/airflow/models/dagbag.py", line 302, in _load_modules_from_file
    loader.exec_module(new_module)
  File "<frozen importlib._bootstrap_external>", line 678, in exec_module
  File "<frozen importlib._bootstrap>", line 219, in _call_with_frames_removed
  File "/opt/airflow/dags/dag_trigger_airbyte_connection.py", line 4, in <module>
    from plugin.operator import AirbyteTriggerSyncOperator
ModuleNotFoundError: No module named 'plugin'
[2021-02-23 23:34:24,786] {scheduler_job.py:641} WARNING - No viable dags retrieved from /opt/airflow/dags/dag_trigger_airbyte_connection.py
[2021-02-23 23:34:24,841] {scheduler_job.py:190} INFO - Processing /opt/airflow/dags/dag_trigger_airbyte_connection.py took 0.065 seconds
[2021-02-23 23:34:54,863] {scheduler_job.py:182} INFO - Started process (PID=491) to work on /opt/airflow/dags/dag_trigger_airbyte_connection.py
[2021-02-23 23:34:54,864] {scheduler_job.py:629} INFO - Processing file /opt/airflow/dags/dag_trigger_airbyte_connection.py for tasks to queue
[2021-02-23 23:34:54,864] {logging_mixin.py:104} INFO - [2021-02-23 23:34:54,864] {dagbag.py:448} INFO - Filling up the DagBag from /opt/airflow/dags/dag_trigger_airbyte_connection.py
[2021-02-23 23:34:54,866] {logging_mixin.py:104} INFO - [2021-02-23 23:34:54,866] {dagbag.py:305} ERROR - Failed to import: /opt/airflow/dags/dag_trigger_airbyte_connection.py
Traceback (most recent call last):
  File "/home/airflow/.local/lib/python3.6/site-packages/airflow/models/dagbag.py", line 302, in _load_modules_from_file
    loader.exec_module(new_module)
  File "<frozen importlib._bootstrap_external>", line 678, in exec_module
  File "<frozen importlib._bootstrap>", line 219, in _call_with_frames_removed
  File "/opt/airflow/dags/dag_trigger_airbyte_connection.py", line 4, in <module>
    from plugin.operator import AirbyteTriggerSyncOperator
ModuleNotFoundError: No module named 'plugin'
[2021-02-23 23:34:54,866] {scheduler_job.py:641} WARNING - No viable dags retrieved from /opt/airflow/dags/dag_trigger_airbyte_connection.py
[2021-02-23 23:34:54,905] {scheduler_job.py:190} INFO - Processing /opt/airflow/dags/dag_trigger_airbyte_connection.py took 0.044 seconds
[2021-02-23 23:35:24,986] {scheduler_job.py:182} INFO - Started process (PID=517) to work on /opt/airflow/dags/dag_trigger_airbyte_connection.py
[2021-02-23 23:35:24,987] {scheduler_job.py:629} INFO - Processing file /opt/airflow/dags/dag_trigger_airbyte_connection.py for tasks to queue
[2021-02-23 23:35:24,988] {logging_mixin.py:104} INFO - [2021-02-23 23:35:24,988] {dagbag.py:448} INFO - Filling up the DagBag from /opt/airflow/dags/dag_trigger_airbyte_connection.py
[2021-02-23 23:35:24,990] {logging_mixin.py:104} INFO - [2021-02-23 23:35:24,990] {dagbag.py:305} ERROR - Failed to import: /opt/airflow/dags/dag_trigger_airbyte_connection.py
Traceback (most recent call last):
  File "/home/airflow/.local/lib/python3.6/site-packages/airflow/models/dagbag.py", line 302, in _load_modules_from_file
    loader.exec_module(new_module)
  File "<frozen importlib._bootstrap_external>", line 678, in exec_module
  File "<frozen importlib._bootstrap>", line 219, in _call_with_frames_removed
  File "/opt/airflow/dags/dag_trigger_airbyte_connection.py", line 4, in <module>
    from plugin.operator import AirbyteTriggerSyncOperator
ModuleNotFoundError: No module named 'plugin'
[2021-02-23 23:35:24,991] {scheduler_job.py:641} WARNING - No viable dags retrieved from /opt/airflow/dags/dag_trigger_airbyte_connection.py
[2021-02-23 23:35:25,030] {scheduler_job.py:190} INFO - Processing /opt/airflow/dags/dag_trigger_airbyte_connection.py took 0.047 seconds
[2021-02-23 23:35:55,835] {scheduler_job.py:182} INFO - Started process (PID=540) to work on /opt/airflow/dags/dag_trigger_airbyte_connection.py
[2021-02-23 23:35:55,836] {scheduler_job.py:629} INFO - Processing file /opt/airflow/dags/dag_trigger_airbyte_connection.py for tasks to queue
[2021-02-23 23:35:55,837] {logging_mixin.py:104} INFO - [2021-02-23 23:35:55,837] {dagbag.py:448} INFO - Filling up the DagBag from /opt/airflow/dags/dag_trigger_airbyte_connection.py
[2021-02-23 23:35:55,839] {logging_mixin.py:104} INFO - [2021-02-23 23:35:55,838] {dagbag.py:305} ERROR - Failed to import: /opt/airflow/dags/dag_trigger_airbyte_connection.py
Traceback (most recent call last):
  File "/home/airflow/.local/lib/python3.6/site-packages/airflow/models/dagbag.py", line 302, in _load_modules_from_file
    loader.exec_module(new_module)
  File "<frozen importlib._bootstrap_external>", line 678, in exec_module
  File "<frozen importlib._bootstrap>", line 219, in _call_with_frames_removed
  File "/opt/airflow/dags/dag_trigger_airbyte_connection.py", line 4, in <module>
    from plugin.operator import AirbyteTriggerSyncOperator
ModuleNotFoundError: No module named 'plugin'
[2021-02-23 23:35:55,839] {scheduler_job.py:641} WARNING - No viable dags retrieved from /opt/airflow/dags/dag_trigger_airbyte_connection.py
[2021-02-23 23:35:55,904] {scheduler_job.py:190} INFO - Processing /opt/airflow/dags/dag_trigger_airbyte_connection.py took 0.071 seconds
[2021-02-23 23:36:25,943] {scheduler_job.py:182} INFO - Started process (PID=566) to work on /opt/airflow/dags/dag_trigger_airbyte_connection.py
[2021-02-23 23:36:25,946] {scheduler_job.py:629} INFO - Processing file /opt/airflow/dags/dag_trigger_airbyte_connection.py for tasks to queue
[2021-02-23 23:36:25,948] {logging_mixin.py:104} INFO - [2021-02-23 23:36:25,947] {dagbag.py:448} INFO - Filling up the DagBag from /opt/airflow/dags/dag_trigger_airbyte_connection.py
[2021-02-23 23:36:25,954] {logging_mixin.py:104} INFO - [2021-02-23 23:36:25,953] {dagbag.py:305} ERROR - Failed to import: /opt/airflow/dags/dag_trigger_airbyte_connection.py
Traceback (most recent call last):
  File "/home/airflow/.local/lib/python3.6/site-packages/airflow/models/dagbag.py", line 302, in _load_modules_from_file
    loader.exec_module(new_module)
  File "<frozen importlib._bootstrap_external>", line 678, in exec_module
  File "<frozen importlib._bootstrap>", line 219, in _call_with_frames_removed
  File "/opt/airflow/dags/dag_trigger_airbyte_connection.py", line 4, in <module>
    from plugin.operator import AirbyteTriggerSyncOperator
ModuleNotFoundError: No module named 'plugin'
[2021-02-23 23:36:25,955] {scheduler_job.py:641} WARNING - No viable dags retrieved from /opt/airflow/dags/dag_trigger_airbyte_connection.py
[2021-02-23 23:36:26,006] {scheduler_job.py:190} INFO - Processing /opt/airflow/dags/dag_trigger_airbyte_connection.py took 0.075 seconds
[2021-02-23 23:36:57,104] {scheduler_job.py:182} INFO - Started process (PID=600) to work on /opt/airflow/dags/dag_trigger_airbyte_connection.py
[2021-02-23 23:36:57,105] {scheduler_job.py:629} INFO - Processing file /opt/airflow/dags/dag_trigger_airbyte_connection.py for tasks to queue
[2021-02-23 23:36:57,106] {logging_mixin.py:104} INFO - [2021-02-23 23:36:57,106] {dagbag.py:448} INFO - Filling up the DagBag from /opt/airflow/dags/dag_trigger_airbyte_connection.py
[2021-02-23 23:36:57,108] {logging_mixin.py:104} INFO - [2021-02-23 23:36:57,107] {dagbag.py:305} ERROR - Failed to import: /opt/airflow/dags/dag_trigger_airbyte_connection.py
Traceback (most recent call last):
  File "/home/airflow/.local/lib/python3.6/site-packages/airflow/models/dagbag.py", line 302, in _load_modules_from_file
    loader.exec_module(new_module)
  File "<frozen importlib._bootstrap_external>", line 678, in exec_module
  File "<frozen importlib._bootstrap>", line 219, in _call_with_frames_removed
  File "/opt/airflow/dags/dag_trigger_airbyte_connection.py", line 4, in <module>
    from plugin.operator import AirbyteTriggerSyncOperator
ModuleNotFoundError: No module named 'plugin'
[2021-02-23 23:36:57,109] {scheduler_job.py:641} WARNING - No viable dags retrieved from /opt/airflow/dags/dag_trigger_airbyte_connection.py
[2021-02-23 23:36:57,153] {scheduler_job.py:190} INFO - Processing /opt/airflow/dags/dag_trigger_airbyte_connection.py took 0.052 seconds
[2021-02-23 23:37:28,867] {scheduler_job.py:182} INFO - Started process (PID=627) to work on /opt/airflow/dags/dag_trigger_airbyte_connection.py
[2021-02-23 23:37:28,868] {scheduler_job.py:629} INFO - Processing file /opt/airflow/dags/dag_trigger_airbyte_connection.py for tasks to queue
[2021-02-23 23:37:28,869] {logging_mixin.py:104} INFO - [2021-02-23 23:37:28,869] {dagbag.py:448} INFO - Filling up the DagBag from /opt/airflow/dags/dag_trigger_airbyte_connection.py
[2021-02-23 23:37:28,871] {logging_mixin.py:104} INFO - [2021-02-23 23:37:28,870] {dagbag.py:305} ERROR - Failed to import: /opt/airflow/dags/dag_trigger_airbyte_connection.py
Traceback (most recent call last):
  File "/home/airflow/.local/lib/python3.6/site-packages/airflow/models/dagbag.py", line 302, in _load_modules_from_file
    loader.exec_module(new_module)
  File "<frozen importlib._bootstrap_external>", line 678, in exec_module
  File "<frozen importlib._bootstrap>", line 219, in _call_with_frames_removed
  File "/opt/airflow/dags/dag_trigger_airbyte_connection.py", line 4, in <module>
    from plugin.operator import AirbyteTriggerSyncOperator
ModuleNotFoundError: No module named 'plugin'
[2021-02-23 23:37:28,871] {scheduler_job.py:641} WARNING - No viable dags retrieved from /opt/airflow/dags/dag_trigger_airbyte_connection.py
[2021-02-23 23:37:28,908] {scheduler_job.py:190} INFO - Processing /opt/airflow/dags/dag_trigger_airbyte_connection.py took 0.044 seconds
[2021-02-23 23:38:00,222] {scheduler_job.py:182} INFO - Started process (PID=657) to work on /opt/airflow/dags/dag_trigger_airbyte_connection.py
[2021-02-23 23:38:00,223] {scheduler_job.py:629} INFO - Processing file /opt/airflow/dags/dag_trigger_airbyte_connection.py for tasks to queue
[2021-02-23 23:38:00,224] {logging_mixin.py:104} INFO - [2021-02-23 23:38:00,224] {dagbag.py:448} INFO - Filling up the DagBag from /opt/airflow/dags/dag_trigger_airbyte_connection.py
[2021-02-23 23:38:00,227] {logging_mixin.py:104} INFO - [2021-02-23 23:38:00,225] {dagbag.py:305} ERROR - Failed to import: /opt/airflow/dags/dag_trigger_airbyte_connection.py
Traceback (most recent call last):
  File "/home/airflow/.local/lib/python3.6/site-packages/airflow/models/dagbag.py", line 302, in _load_modules_from_file
    loader.exec_module(new_module)
  File "<frozen importlib._bootstrap_external>", line 678, in exec_module
  File "<frozen importlib._bootstrap>", line 219, in _call_with_frames_removed
  File "/opt/airflow/dags/dag_trigger_airbyte_connection.py", line 4, in <module>
    from plugin.operator import AirbyteTriggerSyncOperator
ModuleNotFoundError: No module named 'plugin'
[2021-02-23 23:38:00,227] {scheduler_job.py:641} WARNING - No viable dags retrieved from /opt/airflow/dags/dag_trigger_airbyte_connection.py
[2021-02-23 23:38:00,293] {scheduler_job.py:190} INFO - Processing /opt/airflow/dags/dag_trigger_airbyte_connection.py took 0.074 seconds
[2021-02-23 23:38:30,737] {scheduler_job.py:182} INFO - Started process (PID=679) to work on /opt/airflow/dags/dag_trigger_airbyte_connection.py
[2021-02-23 23:38:30,739] {scheduler_job.py:629} INFO - Processing file /opt/airflow/dags/dag_trigger_airbyte_connection.py for tasks to queue
[2021-02-23 23:38:30,740] {logging_mixin.py:104} INFO - [2021-02-23 23:38:30,739] {dagbag.py:448} INFO - Filling up the DagBag from /opt/airflow/dags/dag_trigger_airbyte_connection.py
[2021-02-23 23:38:30,743] {logging_mixin.py:104} INFO - [2021-02-23 23:38:30,742] {dagbag.py:305} ERROR - Failed to import: /opt/airflow/dags/dag_trigger_airbyte_connection.py
Traceback (most recent call last):
  File "/home/airflow/.local/lib/python3.6/site-packages/airflow/models/dagbag.py", line 302, in _load_modules_from_file
    loader.exec_module(new_module)
  File "<frozen importlib._bootstrap_external>", line 678, in exec_module
  File "<frozen importlib._bootstrap>", line 219, in _call_with_frames_removed
  File "/opt/airflow/dags/dag_trigger_airbyte_connection.py", line 4, in <module>
    from plugin.operator import AirbyteTriggerSyncOperator
ModuleNotFoundError: No module named 'plugin'
[2021-02-23 23:38:30,744] {scheduler_job.py:641} WARNING - No viable dags retrieved from /opt/airflow/dags/dag_trigger_airbyte_connection.py
[2021-02-23 23:38:30,801] {scheduler_job.py:190} INFO - Processing /opt/airflow/dags/dag_trigger_airbyte_connection.py took 0.067 seconds
[2021-02-23 23:39:01,310] {scheduler_job.py:182} INFO - Started process (PID=706) to work on /opt/airflow/dags/dag_trigger_airbyte_connection.py
[2021-02-23 23:39:01,312] {scheduler_job.py:629} INFO - Processing file /opt/airflow/dags/dag_trigger_airbyte_connection.py for tasks to queue
[2021-02-23 23:39:01,313] {logging_mixin.py:104} INFO - [2021-02-23 23:39:01,313] {dagbag.py:448} INFO - Filling up the DagBag from /opt/airflow/dags/dag_trigger_airbyte_connection.py
[2021-02-23 23:39:01,317] {logging_mixin.py:104} INFO - [2021-02-23 23:39:01,316] {dagbag.py:305} ERROR - Failed to import: /opt/airflow/dags/dag_trigger_airbyte_connection.py
Traceback (most recent call last):
  File "/home/airflow/.local/lib/python3.6/site-packages/airflow/models/dagbag.py", line 302, in _load_modules_from_file
    loader.exec_module(new_module)
  File "<frozen importlib._bootstrap_external>", line 678, in exec_module
  File "<frozen importlib._bootstrap>", line 219, in _call_with_frames_removed
  File "/opt/airflow/dags/dag_trigger_airbyte_connection.py", line 4, in <module>
    from plugin.operator import AirbyteTriggerSyncOperator
ModuleNotFoundError: No module named 'plugin'
[2021-02-23 23:39:01,318] {scheduler_job.py:641} WARNING - No viable dags retrieved from /opt/airflow/dags/dag_trigger_airbyte_connection.py
[2021-02-23 23:39:01,360] {scheduler_job.py:190} INFO - Processing /opt/airflow/dags/dag_trigger_airbyte_connection.py took 0.057 seconds
[2021-02-23 23:39:31,478] {scheduler_job.py:182} INFO - Started process (PID=733) to work on /opt/airflow/dags/dag_trigger_airbyte_connection.py
[2021-02-23 23:39:31,482] {scheduler_job.py:629} INFO - Processing file /opt/airflow/dags/dag_trigger_airbyte_connection.py for tasks to queue
[2021-02-23 23:39:31,484] {logging_mixin.py:104} INFO - [2021-02-23 23:39:31,484] {dagbag.py:448} INFO - Filling up the DagBag from /opt/airflow/dags/dag_trigger_airbyte_connection.py
[2021-02-23 23:39:31,490] {logging_mixin.py:104} INFO - [2021-02-23 23:39:31,488] {dagbag.py:305} ERROR - Failed to import: /opt/airflow/dags/dag_trigger_airbyte_connection.py
Traceback (most recent call last):
  File "/home/airflow/.local/lib/python3.6/site-packages/airflow/models/dagbag.py", line 302, in _load_modules_from_file
    loader.exec_module(new_module)
  File "<frozen importlib._bootstrap_external>", line 678, in exec_module
  File "<frozen importlib._bootstrap>", line 219, in _call_with_frames_removed
  File "/opt/airflow/dags/dag_trigger_airbyte_connection.py", line 4, in <module>
    from plugin.operator import AirbyteTriggerSyncOperator
ModuleNotFoundError: No module named 'plugin'
[2021-02-23 23:39:31,491] {scheduler_job.py:641} WARNING - No viable dags retrieved from /opt/airflow/dags/dag_trigger_airbyte_connection.py
[2021-02-23 23:39:31,551] {scheduler_job.py:190} INFO - Processing /opt/airflow/dags/dag_trigger_airbyte_connection.py took 0.083 seconds
[2021-02-23 23:40:01,678] {scheduler_job.py:182} INFO - Started process (PID=760) to work on /opt/airflow/dags/dag_trigger_airbyte_connection.py
[2021-02-23 23:40:01,679] {scheduler_job.py:629} INFO - Processing file /opt/airflow/dags/dag_trigger_airbyte_connection.py for tasks to queue
[2021-02-23 23:40:01,680] {logging_mixin.py:104} INFO - [2021-02-23 23:40:01,680] {dagbag.py:448} INFO - Filling up the DagBag from /opt/airflow/dags/dag_trigger_airbyte_connection.py
[2021-02-23 23:40:01,683] {logging_mixin.py:104} INFO - [2021-02-23 23:40:01,682] {dagbag.py:305} ERROR - Failed to import: /opt/airflow/dags/dag_trigger_airbyte_connection.py
Traceback (most recent call last):
  File "/home/airflow/.local/lib/python3.6/site-packages/airflow/models/dagbag.py", line 302, in _load_modules_from_file
    loader.exec_module(new_module)
  File "<frozen importlib._bootstrap_external>", line 678, in exec_module
  File "<frozen importlib._bootstrap>", line 219, in _call_with_frames_removed
  File "/opt/airflow/dags/dag_trigger_airbyte_connection.py", line 4, in <module>
    from plugin.operator import AirbyteTriggerSyncOperator
ModuleNotFoundError: No module named 'plugin'
[2021-02-23 23:40:01,684] {scheduler_job.py:641} WARNING - No viable dags retrieved from /opt/airflow/dags/dag_trigger_airbyte_connection.py
[2021-02-23 23:40:01,778] {scheduler_job.py:190} INFO - Processing /opt/airflow/dags/dag_trigger_airbyte_connection.py took 0.107 seconds
[2021-02-23 23:40:32,229] {scheduler_job.py:182} INFO - Started process (PID=787) to work on /opt/airflow/dags/dag_trigger_airbyte_connection.py
[2021-02-23 23:40:32,232] {scheduler_job.py:629} INFO - Processing file /opt/airflow/dags/dag_trigger_airbyte_connection.py for tasks to queue
[2021-02-23 23:40:32,235] {logging_mixin.py:104} INFO - [2021-02-23 23:40:32,234] {dagbag.py:448} INFO - Filling up the DagBag from /opt/airflow/dags/dag_trigger_airbyte_connection.py
[2021-02-23 23:40:32,241] {logging_mixin.py:104} INFO - [2021-02-23 23:40:32,240] {dagbag.py:305} ERROR - Failed to import: /opt/airflow/dags/dag_trigger_airbyte_connection.py
Traceback (most recent call last):
  File "/home/airflow/.local/lib/python3.6/site-packages/airflow/models/dagbag.py", line 302, in _load_modules_from_file
    loader.exec_module(new_module)
  File "<frozen importlib._bootstrap_external>", line 678, in exec_module
  File "<frozen importlib._bootstrap>", line 219, in _call_with_frames_removed
  File "/opt/airflow/dags/dag_trigger_airbyte_connection.py", line 4, in <module>
    from plugin.operator import AirbyteTriggerSyncOperator
ModuleNotFoundError: No module named 'plugin'
[2021-02-23 23:40:32,242] {scheduler_job.py:641} WARNING - No viable dags retrieved from /opt/airflow/dags/dag_trigger_airbyte_connection.py
[2021-02-23 23:40:32,313] {scheduler_job.py:190} INFO - Processing /opt/airflow/dags/dag_trigger_airbyte_connection.py took 0.094 seconds
[2021-02-23 23:41:02,971] {scheduler_job.py:182} INFO - Started process (PID=814) to work on /opt/airflow/dags/dag_trigger_airbyte_connection.py
[2021-02-23 23:41:02,972] {scheduler_job.py:629} INFO - Processing file /opt/airflow/dags/dag_trigger_airbyte_connection.py for tasks to queue
[2021-02-23 23:41:02,973] {logging_mixin.py:104} INFO - [2021-02-23 23:41:02,972] {dagbag.py:448} INFO - Filling up the DagBag from /opt/airflow/dags/dag_trigger_airbyte_connection.py
[2021-02-23 23:41:02,975] {logging_mixin.py:104} INFO - [2021-02-23 23:41:02,974] {dagbag.py:305} ERROR - Failed to import: /opt/airflow/dags/dag_trigger_airbyte_connection.py
Traceback (most recent call last):
  File "/home/airflow/.local/lib/python3.6/site-packages/airflow/models/dagbag.py", line 302, in _load_modules_from_file
    loader.exec_module(new_module)
  File "<frozen importlib._bootstrap_external>", line 678, in exec_module
  File "<frozen importlib._bootstrap>", line 219, in _call_with_frames_removed
  File "/opt/airflow/dags/dag_trigger_airbyte_connection.py", line 4, in <module>
    from plugin.operator import AirbyteTriggerSyncOperator
ModuleNotFoundError: No module named 'plugin'
[2021-02-23 23:41:02,976] {scheduler_job.py:641} WARNING - No viable dags retrieved from /opt/airflow/dags/dag_trigger_airbyte_connection.py
[2021-02-23 23:41:03,019] {scheduler_job.py:190} INFO - Processing /opt/airflow/dags/dag_trigger_airbyte_connection.py took 0.052 seconds
[2021-02-23 23:41:33,855] {scheduler_job.py:182} INFO - Started process (PID=841) to work on /opt/airflow/dags/dag_trigger_airbyte_connection.py
[2021-02-23 23:41:33,856] {scheduler_job.py:629} INFO - Processing file /opt/airflow/dags/dag_trigger_airbyte_connection.py for tasks to queue
[2021-02-23 23:41:33,857] {logging_mixin.py:104} INFO - [2021-02-23 23:41:33,857] {dagbag.py:448} INFO - Filling up the DagBag from /opt/airflow/dags/dag_trigger_airbyte_connection.py
[2021-02-23 23:41:33,859] {logging_mixin.py:104} INFO - [2021-02-23 23:41:33,858] {dagbag.py:305} ERROR - Failed to import: /opt/airflow/dags/dag_trigger_airbyte_connection.py
Traceback (most recent call last):
  File "/home/airflow/.local/lib/python3.6/site-packages/airflow/models/dagbag.py", line 302, in _load_modules_from_file
    loader.exec_module(new_module)
  File "<frozen importlib._bootstrap_external>", line 678, in exec_module
  File "<frozen importlib._bootstrap>", line 219, in _call_with_frames_removed
  File "/opt/airflow/dags/dag_trigger_airbyte_connection.py", line 4, in <module>
    from plugin.operator import AirbyteTriggerSyncOperator
ModuleNotFoundError: No module named 'plugin'
[2021-02-23 23:41:33,859] {scheduler_job.py:641} WARNING - No viable dags retrieved from /opt/airflow/dags/dag_trigger_airbyte_connection.py
[2021-02-23 23:41:33,922] {scheduler_job.py:190} INFO - Processing /opt/airflow/dags/dag_trigger_airbyte_connection.py took 0.074 seconds
[2021-02-23 23:42:04,774] {scheduler_job.py:182} INFO - Started process (PID=868) to work on /opt/airflow/dags/dag_trigger_airbyte_connection.py
[2021-02-23 23:42:04,777] {scheduler_job.py:629} INFO - Processing file /opt/airflow/dags/dag_trigger_airbyte_connection.py for tasks to queue
[2021-02-23 23:42:04,779] {logging_mixin.py:104} INFO - [2021-02-23 23:42:04,779] {dagbag.py:448} INFO - Filling up the DagBag from /opt/airflow/dags/dag_trigger_airbyte_connection.py
[2021-02-23 23:42:04,787] {logging_mixin.py:104} INFO - [2021-02-23 23:42:04,784] {dagbag.py:305} ERROR - Failed to import: /opt/airflow/dags/dag_trigger_airbyte_connection.py
Traceback (most recent call last):
  File "/home/airflow/.local/lib/python3.6/site-packages/airflow/models/dagbag.py", line 302, in _load_modules_from_file
    loader.exec_module(new_module)
  File "<frozen importlib._bootstrap_external>", line 678, in exec_module
  File "<frozen importlib._bootstrap>", line 219, in _call_with_frames_removed
  File "/opt/airflow/dags/dag_trigger_airbyte_connection.py", line 4, in <module>
    from plugin.operator import AirbyteTriggerSyncOperator
ModuleNotFoundError: No module named 'plugin'
[2021-02-23 23:42:04,788] {scheduler_job.py:641} WARNING - No viable dags retrieved from /opt/airflow/dags/dag_trigger_airbyte_connection.py
[2021-02-23 23:42:04,916] {scheduler_job.py:190} INFO - Processing /opt/airflow/dags/dag_trigger_airbyte_connection.py took 0.151 seconds
[2021-02-23 23:42:35,098] {scheduler_job.py:182} INFO - Started process (PID=895) to work on /opt/airflow/dags/dag_trigger_airbyte_connection.py
[2021-02-23 23:42:35,098] {scheduler_job.py:629} INFO - Processing file /opt/airflow/dags/dag_trigger_airbyte_connection.py for tasks to queue
[2021-02-23 23:42:35,099] {logging_mixin.py:104} INFO - [2021-02-23 23:42:35,099] {dagbag.py:448} INFO - Filling up the DagBag from /opt/airflow/dags/dag_trigger_airbyte_connection.py
[2021-02-23 23:42:35,100] {logging_mixin.py:104} INFO - [2021-02-23 23:42:35,100] {dagbag.py:305} ERROR - Failed to import: /opt/airflow/dags/dag_trigger_airbyte_connection.py
Traceback (most recent call last):
  File "/home/airflow/.local/lib/python3.6/site-packages/airflow/models/dagbag.py", line 302, in _load_modules_from_file
    loader.exec_module(new_module)
  File "<frozen importlib._bootstrap_external>", line 678, in exec_module
  File "<frozen importlib._bootstrap>", line 219, in _call_with_frames_removed
  File "/opt/airflow/dags/dag_trigger_airbyte_connection.py", line 4, in <module>
    from plugin.operator import AirbyteTriggerSyncOperator
ModuleNotFoundError: No module named 'plugin'
[2021-02-23 23:42:35,100] {scheduler_job.py:641} WARNING - No viable dags retrieved from /opt/airflow/dags/dag_trigger_airbyte_connection.py
[2021-02-23 23:42:35,160] {scheduler_job.py:190} INFO - Processing /opt/airflow/dags/dag_trigger_airbyte_connection.py took 0.064 seconds
[2021-02-23 23:43:05,450] {scheduler_job.py:182} INFO - Started process (PID=922) to work on /opt/airflow/dags/dag_trigger_airbyte_connection.py
[2021-02-23 23:43:05,453] {scheduler_job.py:629} INFO - Processing file /opt/airflow/dags/dag_trigger_airbyte_connection.py for tasks to queue
[2021-02-23 23:43:05,454] {logging_mixin.py:104} INFO - [2021-02-23 23:43:05,454] {dagbag.py:448} INFO - Filling up the DagBag from /opt/airflow/dags/dag_trigger_airbyte_connection.py
[2021-02-23 23:43:05,461] {logging_mixin.py:104} INFO - [2021-02-23 23:43:05,458] {dagbag.py:305} ERROR - Failed to import: /opt/airflow/dags/dag_trigger_airbyte_connection.py
Traceback (most recent call last):
  File "/home/airflow/.local/lib/python3.6/site-packages/airflow/models/dagbag.py", line 302, in _load_modules_from_file
    loader.exec_module(new_module)
  File "<frozen importlib._bootstrap_external>", line 678, in exec_module
  File "<frozen importlib._bootstrap>", line 219, in _call_with_frames_removed
  File "/opt/airflow/dags/dag_trigger_airbyte_connection.py", line 4, in <module>
    from plugin.operator import AirbyteTriggerSyncOperator
ModuleNotFoundError: No module named 'plugin'
[2021-02-23 23:43:05,462] {scheduler_job.py:641} WARNING - No viable dags retrieved from /opt/airflow/dags/dag_trigger_airbyte_connection.py
[2021-02-23 23:43:05,623] {scheduler_job.py:190} INFO - Processing /opt/airflow/dags/dag_trigger_airbyte_connection.py took 0.181 seconds
[2021-02-23 23:43:36,533] {scheduler_job.py:182} INFO - Started process (PID=955) to work on /opt/airflow/dags/dag_trigger_airbyte_connection.py
[2021-02-23 23:43:36,534] {scheduler_job.py:629} INFO - Processing file /opt/airflow/dags/dag_trigger_airbyte_connection.py for tasks to queue
[2021-02-23 23:43:36,535] {logging_mixin.py:104} INFO - [2021-02-23 23:43:36,535] {dagbag.py:448} INFO - Filling up the DagBag from /opt/airflow/dags/dag_trigger_airbyte_connection.py
[2021-02-23 23:43:36,537] {logging_mixin.py:104} INFO - [2021-02-23 23:43:36,536] {dagbag.py:305} ERROR - Failed to import: /opt/airflow/dags/dag_trigger_airbyte_connection.py
Traceback (most recent call last):
  File "/home/airflow/.local/lib/python3.6/site-packages/airflow/models/dagbag.py", line 302, in _load_modules_from_file
    loader.exec_module(new_module)
  File "<frozen importlib._bootstrap_external>", line 678, in exec_module
  File "<frozen importlib._bootstrap>", line 219, in _call_with_frames_removed
  File "/opt/airflow/dags/dag_trigger_airbyte_connection.py", line 4, in <module>
    from plugin.operator import AirbyteTriggerSyncOperator
ModuleNotFoundError: No module named 'plugin'
[2021-02-23 23:43:36,537] {scheduler_job.py:641} WARNING - No viable dags retrieved from /opt/airflow/dags/dag_trigger_airbyte_connection.py
[2021-02-23 23:43:36,579] {scheduler_job.py:190} INFO - Processing /opt/airflow/dags/dag_trigger_airbyte_connection.py took 0.048 seconds
[2021-02-23 23:44:06,698] {scheduler_job.py:182} INFO - Started process (PID=980) to work on /opt/airflow/dags/dag_trigger_airbyte_connection.py
[2021-02-23 23:44:06,698] {scheduler_job.py:629} INFO - Processing file /opt/airflow/dags/dag_trigger_airbyte_connection.py for tasks to queue
[2021-02-23 23:44:06,699] {logging_mixin.py:104} INFO - [2021-02-23 23:44:06,699] {dagbag.py:448} INFO - Filling up the DagBag from /opt/airflow/dags/dag_trigger_airbyte_connection.py
[2021-02-23 23:44:06,701] {logging_mixin.py:104} INFO - [2021-02-23 23:44:06,700] {dagbag.py:305} ERROR - Failed to import: /opt/airflow/dags/dag_trigger_airbyte_connection.py
Traceback (most recent call last):
  File "/home/airflow/.local/lib/python3.6/site-packages/airflow/models/dagbag.py", line 302, in _load_modules_from_file
    loader.exec_module(new_module)
  File "<frozen importlib._bootstrap_external>", line 678, in exec_module
  File "<frozen importlib._bootstrap>", line 219, in _call_with_frames_removed
  File "/opt/airflow/dags/dag_trigger_airbyte_connection.py", line 4, in <module>
    from plugin.operator import AirbyteTriggerSyncOperator
ModuleNotFoundError: No module named 'plugin'
[2021-02-23 23:44:06,701] {scheduler_job.py:641} WARNING - No viable dags retrieved from /opt/airflow/dags/dag_trigger_airbyte_connection.py
[2021-02-23 23:44:06,743] {scheduler_job.py:190} INFO - Processing /opt/airflow/dags/dag_trigger_airbyte_connection.py took 0.048 seconds
[2021-02-23 23:44:36,826] {scheduler_job.py:182} INFO - Started process (PID=1005) to work on /opt/airflow/dags/dag_trigger_airbyte_connection.py
[2021-02-23 23:44:36,829] {scheduler_job.py:629} INFO - Processing file /opt/airflow/dags/dag_trigger_airbyte_connection.py for tasks to queue
[2021-02-23 23:44:36,832] {logging_mixin.py:104} INFO - [2021-02-23 23:44:36,831] {dagbag.py:448} INFO - Filling up the DagBag from /opt/airflow/dags/dag_trigger_airbyte_connection.py
[2021-02-23 23:44:36,838] {logging_mixin.py:104} INFO - [2021-02-23 23:44:36,836] {dagbag.py:305} ERROR - Failed to import: /opt/airflow/dags/dag_trigger_airbyte_connection.py
Traceback (most recent call last):
  File "/home/airflow/.local/lib/python3.6/site-packages/airflow/models/dagbag.py", line 302, in _load_modules_from_file
    loader.exec_module(new_module)
  File "<frozen importlib._bootstrap_external>", line 678, in exec_module
  File "<frozen importlib._bootstrap>", line 219, in _call_with_frames_removed
  File "/opt/airflow/dags/dag_trigger_airbyte_connection.py", line 4, in <module>
    from plugin.operator import AirbyteTriggerSyncOperator
ModuleNotFoundError: No module named 'plugin'
[2021-02-23 23:44:36,839] {scheduler_job.py:641} WARNING - No viable dags retrieved from /opt/airflow/dags/dag_trigger_airbyte_connection.py
[2021-02-23 23:44:36,883] {scheduler_job.py:190} INFO - Processing /opt/airflow/dags/dag_trigger_airbyte_connection.py took 0.065 seconds
[2021-02-23 23:45:07,057] {scheduler_job.py:182} INFO - Started process (PID=1031) to work on /opt/airflow/dags/dag_trigger_airbyte_connection.py
[2021-02-23 23:45:07,060] {scheduler_job.py:629} INFO - Processing file /opt/airflow/dags/dag_trigger_airbyte_connection.py for tasks to queue
[2021-02-23 23:45:07,062] {logging_mixin.py:104} INFO - [2021-02-23 23:45:07,062] {dagbag.py:448} INFO - Filling up the DagBag from /opt/airflow/dags/dag_trigger_airbyte_connection.py
[2021-02-23 23:45:07,069] {logging_mixin.py:104} INFO - [2021-02-23 23:45:07,067] {dagbag.py:305} ERROR - Failed to import: /opt/airflow/dags/dag_trigger_airbyte_connection.py
Traceback (most recent call last):
  File "/home/airflow/.local/lib/python3.6/site-packages/airflow/models/dagbag.py", line 302, in _load_modules_from_file
    loader.exec_module(new_module)
  File "<frozen importlib._bootstrap_external>", line 678, in exec_module
  File "<frozen importlib._bootstrap>", line 219, in _call_with_frames_removed
  File "/opt/airflow/dags/dag_trigger_airbyte_connection.py", line 4, in <module>
    from plugin.operator import AirbyteTriggerSyncOperator
ModuleNotFoundError: No module named 'plugin'
[2021-02-23 23:45:07,069] {scheduler_job.py:641} WARNING - No viable dags retrieved from /opt/airflow/dags/dag_trigger_airbyte_connection.py
[2021-02-23 23:45:07,239] {scheduler_job.py:190} INFO - Processing /opt/airflow/dags/dag_trigger_airbyte_connection.py took 0.191 seconds
[2021-02-23 23:45:37,303] {scheduler_job.py:182} INFO - Started process (PID=1058) to work on /opt/airflow/dags/dag_trigger_airbyte_connection.py
[2021-02-23 23:45:37,305] {scheduler_job.py:629} INFO - Processing file /opt/airflow/dags/dag_trigger_airbyte_connection.py for tasks to queue
[2021-02-23 23:45:37,306] {logging_mixin.py:104} INFO - [2021-02-23 23:45:37,305] {dagbag.py:448} INFO - Filling up the DagBag from /opt/airflow/dags/dag_trigger_airbyte_connection.py
[2021-02-23 23:45:37,308] {logging_mixin.py:104} INFO - [2021-02-23 23:45:37,307] {dagbag.py:305} ERROR - Failed to import: /opt/airflow/dags/dag_trigger_airbyte_connection.py
Traceback (most recent call last):
  File "/home/airflow/.local/lib/python3.6/site-packages/airflow/models/dagbag.py", line 302, in _load_modules_from_file
    loader.exec_module(new_module)
  File "<frozen importlib._bootstrap_external>", line 678, in exec_module
  File "<frozen importlib._bootstrap>", line 219, in _call_with_frames_removed
  File "/opt/airflow/dags/dag_trigger_airbyte_connection.py", line 4, in <module>
    from plugin.operator import AirbyteTriggerSyncOperator
ModuleNotFoundError: No module named 'plugin'
[2021-02-23 23:45:37,309] {scheduler_job.py:641} WARNING - No viable dags retrieved from /opt/airflow/dags/dag_trigger_airbyte_connection.py
[2021-02-23 23:45:37,353] {scheduler_job.py:190} INFO - Processing /opt/airflow/dags/dag_trigger_airbyte_connection.py took 0.054 seconds
[2021-02-23 23:46:07,960] {scheduler_job.py:182} INFO - Started process (PID=1084) to work on /opt/airflow/dags/dag_trigger_airbyte_connection.py
[2021-02-23 23:46:07,962] {scheduler_job.py:629} INFO - Processing file /opt/airflow/dags/dag_trigger_airbyte_connection.py for tasks to queue
[2021-02-23 23:46:07,963] {logging_mixin.py:104} INFO - [2021-02-23 23:46:07,963] {dagbag.py:448} INFO - Filling up the DagBag from /opt/airflow/dags/dag_trigger_airbyte_connection.py
[2021-02-23 23:46:07,967] {logging_mixin.py:104} INFO - [2021-02-23 23:46:07,965] {dagbag.py:305} ERROR - Failed to import: /opt/airflow/dags/dag_trigger_airbyte_connection.py
Traceback (most recent call last):
  File "/home/airflow/.local/lib/python3.6/site-packages/airflow/models/dagbag.py", line 302, in _load_modules_from_file
    loader.exec_module(new_module)
  File "<frozen importlib._bootstrap_external>", line 678, in exec_module
  File "<frozen importlib._bootstrap>", line 219, in _call_with_frames_removed
  File "/opt/airflow/dags/dag_trigger_airbyte_connection.py", line 4, in <module>
    from plugin.operator import AirbyteTriggerSyncOperator
ModuleNotFoundError: No module named 'plugin'
[2021-02-23 23:46:07,968] {scheduler_job.py:641} WARNING - No viable dags retrieved from /opt/airflow/dags/dag_trigger_airbyte_connection.py
[2021-02-23 23:46:08,022] {scheduler_job.py:190} INFO - Processing /opt/airflow/dags/dag_trigger_airbyte_connection.py took 0.073 seconds
[2021-02-23 23:46:38,037] {scheduler_job.py:182} INFO - Started process (PID=1111) to work on /opt/airflow/dags/dag_trigger_airbyte_connection.py
[2021-02-23 23:46:38,038] {scheduler_job.py:629} INFO - Processing file /opt/airflow/dags/dag_trigger_airbyte_connection.py for tasks to queue
[2021-02-23 23:46:38,039] {logging_mixin.py:104} INFO - [2021-02-23 23:46:38,039] {dagbag.py:448} INFO - Filling up the DagBag from /opt/airflow/dags/dag_trigger_airbyte_connection.py
[2021-02-23 23:46:38,041] {logging_mixin.py:104} INFO - [2021-02-23 23:46:38,040] {dagbag.py:305} ERROR - Failed to import: /opt/airflow/dags/dag_trigger_airbyte_connection.py
Traceback (most recent call last):
  File "/home/airflow/.local/lib/python3.6/site-packages/airflow/models/dagbag.py", line 302, in _load_modules_from_file
    loader.exec_module(new_module)
  File "<frozen importlib._bootstrap_external>", line 678, in exec_module
  File "<frozen importlib._bootstrap>", line 219, in _call_with_frames_removed
  File "/opt/airflow/dags/dag_trigger_airbyte_connection.py", line 4, in <module>
    from plugin.operator import AirbyteTriggerSyncOperator
ModuleNotFoundError: No module named 'plugin'
[2021-02-23 23:46:38,041] {scheduler_job.py:641} WARNING - No viable dags retrieved from /opt/airflow/dags/dag_trigger_airbyte_connection.py
[2021-02-23 23:46:38,089] {scheduler_job.py:190} INFO - Processing /opt/airflow/dags/dag_trigger_airbyte_connection.py took 0.055 seconds
[2021-02-23 23:47:09,138] {scheduler_job.py:182} INFO - Started process (PID=1142) to work on /opt/airflow/dags/dag_trigger_airbyte_connection.py
[2021-02-23 23:47:09,139] {scheduler_job.py:629} INFO - Processing file /opt/airflow/dags/dag_trigger_airbyte_connection.py for tasks to queue
[2021-02-23 23:47:09,139] {logging_mixin.py:104} INFO - [2021-02-23 23:47:09,139] {dagbag.py:448} INFO - Filling up the DagBag from /opt/airflow/dags/dag_trigger_airbyte_connection.py
[2021-02-23 23:47:09,142] {logging_mixin.py:104} INFO - [2021-02-23 23:47:09,141] {dagbag.py:305} ERROR - Failed to import: /opt/airflow/dags/dag_trigger_airbyte_connection.py
Traceback (most recent call last):
  File "/home/airflow/.local/lib/python3.6/site-packages/airflow/models/dagbag.py", line 302, in _load_modules_from_file
    loader.exec_module(new_module)
  File "<frozen importlib._bootstrap_external>", line 678, in exec_module
  File "<frozen importlib._bootstrap>", line 219, in _call_with_frames_removed
  File "/opt/airflow/dags/dag_trigger_airbyte_connection.py", line 4, in <module>
    from plugin.operator import AirbyteTriggerSyncOperator
ModuleNotFoundError: No module named 'plugin'
[2021-02-23 23:47:09,142] {scheduler_job.py:641} WARNING - No viable dags retrieved from /opt/airflow/dags/dag_trigger_airbyte_connection.py
[2021-02-23 23:47:09,191] {scheduler_job.py:190} INFO - Processing /opt/airflow/dags/dag_trigger_airbyte_connection.py took 0.056 seconds
[2021-02-23 23:47:40,161] {scheduler_job.py:182} INFO - Started process (PID=1169) to work on /opt/airflow/dags/dag_trigger_airbyte_connection.py
[2021-02-23 23:47:40,162] {scheduler_job.py:629} INFO - Processing file /opt/airflow/dags/dag_trigger_airbyte_connection.py for tasks to queue
[2021-02-23 23:47:40,162] {logging_mixin.py:104} INFO - [2021-02-23 23:47:40,162] {dagbag.py:448} INFO - Filling up the DagBag from /opt/airflow/dags/dag_trigger_airbyte_connection.py
[2021-02-23 23:47:40,164] {logging_mixin.py:104} INFO - [2021-02-23 23:47:40,163] {dagbag.py:305} ERROR - Failed to import: /opt/airflow/dags/dag_trigger_airbyte_connection.py
Traceback (most recent call last):
  File "/home/airflow/.local/lib/python3.6/site-packages/airflow/models/dagbag.py", line 302, in _load_modules_from_file
    loader.exec_module(new_module)
  File "<frozen importlib._bootstrap_external>", line 678, in exec_module
  File "<frozen importlib._bootstrap>", line 219, in _call_with_frames_removed
  File "/opt/airflow/dags/dag_trigger_airbyte_connection.py", line 4, in <module>
    from plugin.operator import AirbyteTriggerSyncOperator
ModuleNotFoundError: No module named 'plugin'
[2021-02-23 23:47:40,164] {scheduler_job.py:641} WARNING - No viable dags retrieved from /opt/airflow/dags/dag_trigger_airbyte_connection.py
[2021-02-23 23:47:40,202] {scheduler_job.py:190} INFO - Processing /opt/airflow/dags/dag_trigger_airbyte_connection.py took 0.044 seconds
[2021-02-23 23:48:11,308] {scheduler_job.py:182} INFO - Started process (PID=1196) to work on /opt/airflow/dags/dag_trigger_airbyte_connection.py
[2021-02-23 23:48:11,308] {scheduler_job.py:629} INFO - Processing file /opt/airflow/dags/dag_trigger_airbyte_connection.py for tasks to queue
[2021-02-23 23:48:11,309] {logging_mixin.py:104} INFO - [2021-02-23 23:48:11,309] {dagbag.py:448} INFO - Filling up the DagBag from /opt/airflow/dags/dag_trigger_airbyte_connection.py
[2021-02-23 23:48:11,311] {logging_mixin.py:104} INFO - [2021-02-23 23:48:11,310] {dagbag.py:305} ERROR - Failed to import: /opt/airflow/dags/dag_trigger_airbyte_connection.py
Traceback (most recent call last):
  File "/home/airflow/.local/lib/python3.6/site-packages/airflow/models/dagbag.py", line 302, in _load_modules_from_file
    loader.exec_module(new_module)
  File "<frozen importlib._bootstrap_external>", line 678, in exec_module
  File "<frozen importlib._bootstrap>", line 219, in _call_with_frames_removed
  File "/opt/airflow/dags/dag_trigger_airbyte_connection.py", line 4, in <module>
    from plugin.operator import AirbyteTriggerSyncOperator
ModuleNotFoundError: No module named 'plugin'
[2021-02-23 23:48:11,311] {scheduler_job.py:641} WARNING - No viable dags retrieved from /opt/airflow/dags/dag_trigger_airbyte_connection.py
[2021-02-23 23:48:11,354] {scheduler_job.py:190} INFO - Processing /opt/airflow/dags/dag_trigger_airbyte_connection.py took 0.048 seconds
[2021-02-23 23:48:41,407] {scheduler_job.py:182} INFO - Started process (PID=1222) to work on /opt/airflow/dags/dag_trigger_airbyte_connection.py
[2021-02-23 23:48:41,408] {scheduler_job.py:629} INFO - Processing file /opt/airflow/dags/dag_trigger_airbyte_connection.py for tasks to queue
[2021-02-23 23:48:41,408] {logging_mixin.py:104} INFO - [2021-02-23 23:48:41,408] {dagbag.py:448} INFO - Filling up the DagBag from /opt/airflow/dags/dag_trigger_airbyte_connection.py
[2021-02-23 23:48:41,410] {logging_mixin.py:104} INFO - [2021-02-23 23:48:41,410] {dagbag.py:305} ERROR - Failed to import: /opt/airflow/dags/dag_trigger_airbyte_connection.py
Traceback (most recent call last):
  File "/home/airflow/.local/lib/python3.6/site-packages/airflow/models/dagbag.py", line 302, in _load_modules_from_file
    loader.exec_module(new_module)
  File "<frozen importlib._bootstrap_external>", line 678, in exec_module
  File "<frozen importlib._bootstrap>", line 219, in _call_with_frames_removed
  File "/opt/airflow/dags/dag_trigger_airbyte_connection.py", line 4, in <module>
    from plugin.operator import AirbyteTriggerSyncOperator
ModuleNotFoundError: No module named 'plugin'
[2021-02-23 23:48:41,411] {scheduler_job.py:641} WARNING - No viable dags retrieved from /opt/airflow/dags/dag_trigger_airbyte_connection.py
[2021-02-23 23:48:41,453] {scheduler_job.py:190} INFO - Processing /opt/airflow/dags/dag_trigger_airbyte_connection.py took 0.048 seconds
[2021-02-23 23:49:12,536] {scheduler_job.py:182} INFO - Started process (PID=1250) to work on /opt/airflow/dags/dag_trigger_airbyte_connection.py
[2021-02-23 23:49:12,537] {scheduler_job.py:629} INFO - Processing file /opt/airflow/dags/dag_trigger_airbyte_connection.py for tasks to queue
[2021-02-23 23:49:12,537] {logging_mixin.py:104} INFO - [2021-02-23 23:49:12,537] {dagbag.py:448} INFO - Filling up the DagBag from /opt/airflow/dags/dag_trigger_airbyte_connection.py
[2021-02-23 23:49:12,539] {logging_mixin.py:104} INFO - [2021-02-23 23:49:12,538] {dagbag.py:305} ERROR - Failed to import: /opt/airflow/dags/dag_trigger_airbyte_connection.py
Traceback (most recent call last):
  File "/home/airflow/.local/lib/python3.6/site-packages/airflow/models/dagbag.py", line 302, in _load_modules_from_file
    loader.exec_module(new_module)
  File "<frozen importlib._bootstrap_external>", line 678, in exec_module
  File "<frozen importlib._bootstrap>", line 219, in _call_with_frames_removed
  File "/opt/airflow/dags/dag_trigger_airbyte_connection.py", line 4, in <module>
    from plugin.operator import AirbyteTriggerSyncOperator
ModuleNotFoundError: No module named 'plugin'
[2021-02-23 23:49:12,539] {scheduler_job.py:641} WARNING - No viable dags retrieved from /opt/airflow/dags/dag_trigger_airbyte_connection.py
[2021-02-23 23:49:12,601] {scheduler_job.py:190} INFO - Processing /opt/airflow/dags/dag_trigger_airbyte_connection.py took 0.068 seconds
